Workbook

Sheet 考勤记录
A1: 工号 | B1: 姓名 | C1: 部门 | D1: 日期 | E1: 上班打卡 | F1: 下班打卡 | G1: 迟到(分钟) | H1: 早退(分钟) | I1: 出勤状态
A2: E001 | B2: 李明 | C2: 销售部 | D2: 2026-09-01 | E2: 08:55 | F2: 18:14 | G2: =IF(E2="","",IF(E2>"09:00",(E2-"09:00")*1440,0)) | H2: 0 | I2: 正常
A3: E001 | B3: 李明 | C3: 销售部 | D3: 2026-09-02 | E3: 09:17 | F3: 18:18 | G3: =IF(E3="","",IF(E3>"09:00",(E3-"09:00")*1440,0)) | H3: 0 | I3: 迟到
A4: E001 | B4: 李明 | C4: 销售部 | D4: 2026-09-03 | E4: 08:55 | F4: 18:18 | G4: =IF(E4="","",IF(E4>"09:00",(E4-"09:00")*1440,0)) | H4: 0 | I4: 正常
A5: E001 | B5: 李明 | C5: 销售部 | D5: 2026-09-04 | E5: 08:55 | F5: 18:34 | G5: =IF(E5="","",IF(E5>"09:00",(E5-"09:00")*1440,0)) | H5: 0 | I5: 正常
A6: E001 | B6: 李明 | C6: 销售部 | D6: 2026-09-07 | I6: 请假
A7: E001 | B7: 李明 | C7: 销售部 | D7: 2026-09-08 | E7: 08:55 | F7: 18:33 | G7: =IF(E7="","",IF(E7>"09:00",(E7-"09:00")*1440,0)) | H7: 0 | I7: 正常
A8: E001 | B8: 李明 | C8: 销售部 | D8: 2026-09-09 | E8: 09:04 | F8: 18:47 | G8: =IF(E8="","",IF(E8>"09:00",(E8-"09:00")*1440,0)) | H8: 0 | I8: 迟到
A9: E001 | B9: 李明 | C9: 销售部 | D9: 2026-09-10 | E9: 08:55 | F9: 18:34 | G9: =IF(E9="","",IF(E9>"09:00",(E9-"09:00")*1440,0)) | H9: 0 | I9: 正常
A10: E001 | B10: 李明 | C10: 销售部 | D10: 2026-09-11 | E10: 08:55 | F10: 18:09 | G10: =IF(E10="","",IF(E10>"09:00",(E10-"09:00")*1440,0)) | H10: 0 | I10: 正常
A11: E001 | B11: 李明 | C11: 销售部 | D11: 2026-09-14 | E11: 09:20 | F11: 18:42 | G11: =IF(E11="","",IF(E11>"09:00",(E11-"09:00")*1440,0)) | H11: 0 | I11: 迟到
A12: E001 | B12: 李明 | C12: 销售部 | D12: 2026-09-15 | E12: 08:59 | F12: 18:27 | G12: =IF(E12="","",IF(E12>"09:00",(E12-"09:00")*1440,0)) | H12: 0 | I12: 迟到
A13: E001 | B13: 李明 | C13: 销售部 | D13: 2026-09-16 | E13: 08:58 | F13: 18:47 | G13: =IF(E13="","",IF(E13>"09:00",(E13-"09:00")*1440,0)) | H13: 0 | I13: 迟到
A14: E001 | B14: 李明 | C14: 销售部 | D14: 2026-09-17 | E14: 08:55 | F14: 18:21 | G14: =IF(E14="","",IF(E14>"09:00",(E14-"09:00")*1440,0)) | H14: 0 | I14: 正常
A15: E001 | B15: 李明 | C15: 销售部 | D15: 2026-09-18 | E15: 08:55 | F15: 18:22 | G15: =IF(E15="","",IF(E15>"09:00",(E15-"09:00")*1440,0)) | H15: 0 | I15: 正常
A16: E001 | B16: 李明 | C16: 销售部 | D16: 2026-09-21 | E16: 08:55 | F16: 18:11 | G16: =IF(E16="","",IF(E16>"09:00",(E16-"09:00")*1440,0)) | H16: 0 | I16: 正常
A17: E001 | B17: 李明 | C17: 销售部 | D17: 2026-09-22 | I17: 请假
A18: E001 | B18: 李明 | C18: 销售部 | D18: 2026-09-23 | E18: 09:11 | F18: 18:49 | G18: =IF(E18="","",IF(E18>"09:00",(E18-"09:00")*1440,0)) | H18: 0 | I18: 迟到
A19: E001 | B19: 李明 | C19: 销售部 | D19: 2026-09-24 | E19: 08:55 | F19: 18:07 | G19: =IF(E19="","",IF(E19>"09:00",(E19-"09:00")*1440,0)) | H19: 0 | I19: 正常
A20: E001 | B20: 李明 | C20: 销售部 | D20: 2026-09-25 | E20: 09:00 | F20: 18:49 | G20: =IF(E20="","",IF(E20>"09:00",(E20-"09:00")*1440,0)) | H20: 0 | I20: 迟到
A21: E001 | B21: 李明 | C21: 销售部 | D21: 2026-09-28 | E21: 08:55 | F21: 18:09 | G21: =IF(E21="","",IF(E21>"09:00",(E21-"09:00")*1440,0)) | H21: 0 | I21: 正常
A22: E001 | B22: 李明 | C22: 销售部 | D22: 2026-09-29 | E22: 08:55 | F22: 18:12 | G22: =IF(E22="","",IF(E22>"09:00",(E22-"09:00")*1440,0)) | H22: 0 | I22: 正常
A23: E001 | B23: 李明 | C23: 销售部 | D23: 2026-09-30 | E23: 08:55 | F23: 18:07 | G23: =IF(E23="","",IF(E23>"09:00",(E23-"09:00")*1440,0)) | H23: 0 | I23: 正常
A24: E002 | B24: 王芳 | C24: 技术部 | D24: 2026-09-01 | E24: 08:55 | F24: 18:45 | G24: =IF(E24="","",IF(E24>"09:00",(E24-"09:00")*1440,0)) | H24: 0 | I24: 正常
A25: E002 | B25: 王芳 | C25: 技术部 | D25: 2026-09-02 | E25: 08:55 | F25: 18:13 | G25: =IF(E25="","",IF(E25>"09:00",(E25-"09:00")*1440,0)) | H25: 0 | I25: 正常
A26: E002 | B26: 王芳 | C26: 技术部 | D26: 2026-09-03 | E26: 09:16 | F26: 18:40 | G26: =IF(E26="","",IF(E26>"09:00",(E26-"09:00")*1440,0)) | H26: 0 | I26: 迟到
A27: E002 | B27: 王芳 | C27: 技术部 | D27: 2026-09-04 | E27: 09:03 | F27: 18:37 | G27: =IF(E27="","",IF(E27>"09:00",(E27-"09:00")*1440,0)) | H27: 0 | I27: 迟到
A28: E002 | B28: 王芳 | C28: 技术部 | D28: 2026-09-07 | E28: 08:55 | F28: 18:12 | G28: =IF(E28="","",IF(E28>"09:00",(E28-"09:00")*1440,0)) | H28: 0 | I28: 正常
A29: E002 | B29: 王芳 | C29: 技术部 | D29: 2026-09-08 | E29: 08:55 | F29: 18:07 | G29: =IF(E29="","",IF(E29>"09:00",(E29-"09:00")*1440,0)) | H29: 0 | I29: 正常
... A61: E003 | B61: 赵强 | C61: 市场部 | D61: 2026-09-22 | E61: 08:55 | F61: 18:29 | G61: =IF(E61="","",IF(E61>"09:00",(E61-"09:00")*1440,0)) | H61: 0 | I61: 正常
A62: E003 | B62: 赵强 | C62: 市场部 | D62: 2026-09-23 | I62: 请假
A63: E003 | B63: 赵强 | C63: 市场部 | D63: 2026-09-24 | E63: 08:55 | F63: 18:42 | G63: =IF(E63="","",IF(E63>"09:00",(E63-"09:00")*1440,0)) | H63: 0 | I63: 正常
A64: E003 | B64: 赵强 | C64: 市场部 | D64: 2026-09-25 | E64: 08:55 | F64: 18:48 | G64: =IF(E64="","",IF(E64>"09:00",(E64-"09:00")*1440,0)) | H64: 0 | I64: 正常
A65: E003 | B65: 赵强 | C65: 市场部 | D65: 2026-09-28 | E65: 08:55 | F65: 18:24 | G65: =IF(E65="","",IF(E65>"09:00",(E65-"09:00")*1440,0)) | H65: 0 | I65: 正常
A66: E003 | B66: 赵强 | C66: 市场部 | D66: 2026-09-29 | E66: 08:55 | F66: 18:43 | G66: =IF(E66="","",IF(E66>"09:00",(E66-"09:00")*1440,0)) | H66: 0 | I66: 正常
A67: E003 | B67: 赵强 | C67: 市场部 | D67: 2026-09-30 | E67: 08:55 | F67: 18:49 | G67: =IF(E67="","",IF(E67>"09:00",(E67-"09:00")*1440,0)) | H67: 0 | I67: 正常
A68: E004 | B68: 刘洋 | C68: 财务部 | D68: 2026-09-01 | E68: 08:55 | F68: 18:26 | G68: =IF(E68="","",IF(E68>"09:00",(E68-"09:00")*1440,0)) | H68: 0 | I68: 正常
A69: E004 | B69: 刘洋 | C69: 财务部 | D69: 2026-09-02 | E69: 08:55 | F69: 18:45 | G69: =IF(E69="","",IF(E69>"09:00",(E69-"09:00")*1440,0)) | H69: 0 | I69: 正常
A70: E004 | B70: 刘洋 | C70: 财务部 | D70: 2026-09-03 | E70: 08:55 | F70: 18:12 | G70: =IF(E70="","",IF(E70>"09:00",(E70-"09:00")*1440,0)) | H70: 0 | I70: 正常
A71: E004 | B71: 刘洋 | C71: 财务部 | D71: 2026-09-04 | E71: 08:55 | F71: 18:32 | G71: =IF(E71="","",IF(E71>"09:00",(E71-"09:00")*1440,0)) | H71: 0 | I71: 正常
...

Sheet 部门汇总
A1: 部门 | B1: 迟到人次 | C1: 平均迟到分钟 | D1: 请假人次
A2: 销售部 | B2: =COUNTIFS(考勤记录!C:C,A2,考勤记录!I:I,"迟到") | C2: =ROUND(AVERAGEIF(考勤记录!C:C,A2,考勤记录!G:G),1) | D2: =COUNTIFS(考勤记录!C:C,A2,考勤记录!I:I,"请假")
A3: 技术部 | B3: =COUNTIFS(考勤记录!C:C,A3,考勤记录!I:I,"迟到") | C3: =ROUND(AVERAGEIF(考勤记录!C:C,A3,考勤记录!G:G),1) | D3: =COUNTIFS(考勤记录!C:C,A3,考勤记录!I:I,"请假")
A4: 市场部 | B4: =COUNTIFS(考勤记录!C:C,A4,考勤记录!I:I,"迟到") | C4: =ROUND(AVERAGEIF(考勤记录!C:C,A4,考勤记录!G:G),1) | D4: =COUNTIFS(考勤记录!C:C,A4,考勤记录!I:I,"请假")
A5: 财务部 | B5: =COUNTIFS(考勤记录!C:C,A5,考勤记录!I:I,"迟到") | C5: =ROUND(AVERAGEIF(考勤记录!C:C,A5,考勤记录!G:G),1) | D5: =COUNTIFS(考勤记录!C:C,A5,考勤记录!I:I,"请假")
A6: 人事部 | B6: =COUNTIFS(考勤记录!C:C,A6,考勤记录!I:I,"迟到") | C6: =ROUND(AVERAGEIF(考勤记录!C:C,A6,考勤记录!G:G),1) | D6: =COUNTIFS(考勤记录!C:C,A6,考勤记录!I:I,"请假")

Sheet 使用说明
A1: 人事考勤样本 — 练习建议
A2: 1. 迟到(分钟)列用公式 =IF(上班打卡>"09:00",(上班打卡-"09:00")*1440,0)，改打卡时间自动重算。
A3: 2. 部门汇总表用 COUNTIFS/AVERAGEIF 按部门统计，注意跨表引用写法 考勤记录!C:C。
A4: 3. 练习：找出迟到超过 3 次的员工（COUNTIFS 工号+迟到）。
A5: 4. 练习：用数据透视表按「出勤状态」统计各部门人数。
A6: 5. 练习：给迟到>15 分钟的行加条件格式标红。
